<mujoco model = "car">

  <asset>
    <texture type="skybox" builtin="gradient" rgb1="0.6 0.6 0.6" rgb2="0 0 0" width="512" height="512"/>
    <texture name="texplane" type="2d" builtin="checker" rgb1=".25 .25 .25" rgb2=".3 .3 .3" width="512" height="512" mark="cross" markrgb=".8 .8 .8"/>
    <material name="matplane" reflectance="0.3" texture="texplane" texrepeat="1 1" texuniform="true"/>
  </asset>

  <option gravity="0 0 -9.81"/>

  <worldbody>
    <geom name="floor" pos="0 0 0.42" size="0 0 1" type="plane" material="matplane"/>
    <light directional="true" diffuse=".8 .8 .8" specular=".2 .2 .2" pos="0 0 5" dir="0 0 -1"/>

    <body name="car body1" pos="0 0 1">
      <geom type="cylinder" size="1 .2" rgba=".6 .25 .25 1"/>
      <camera name="eye1" pos="0.8 0 0.2"/>
      <joint type="free"/>
      <body name="left wheel1" pos="-0.45 1.2 0" euler="-90 0 0">
        <geom type = "cylinder" size=".58.12" rgba=".2 .4 .7 1"/>
        <joint name="left joint1" type="hinge" pos="0 0 0" axis="0 0 1"/>
        <site name="jl1" type="cylinder" pos="0 0 -0.16" size="0.1 0.3"/>
        <site name="ml1" type="sphere" pos="0 0.3 0.16" size="0.06"/>
      </body>
      <body name="right wheel1" pos="-0.45 -1.2 0" euler="-90 0 0">
        <geom type = "cylinder" size=".58 .12" rgba=".2 .4 .7 1"/>
        <joint name="right joint1" type="hinge" pos="0 0 0" axis="0 0 1"/>
        <site name="jr1" type="cylinder" pos="0 0 0.16" size="0.1 0.3"/>
        <site name="mr1" type="sphere" pos="0 0.3 -0.16" size="0.06"/>
      </body>
      <body name="front wheel1" pos="0.5 0 -0.39">
        <geom type="sphere" size="0.19" rgba=".5 .7 .8 1"/>
        <joint name="sphere wj1" type="ball" pos="0 0 0"/>
      </body>
    </body>

    <body name="car body2" pos="0 4 1" euler="0 0 90">
      <geom type="cylinder" size="1 .2" rgba=".6 .25 .25 1"/>
      <camera name="eye2" pos="0.8 0 0.2"/>
      <joint type="free"/>
      <body name="left wheel2" pos="-0.45 1.2 0" euler="-90 0 0">
        <geom type = "cylinder" size=".58.12" rgba=".2 .4 .7 1"/>
        <joint name="left joint2" type="hinge" pos="0 0 0" axis="0 0 1"/>
        <site name="jl2" type="cylinder" pos="0 0 -0.16" size="0.1 0.3"/>
        <site name="ml2" type="sphere" pos="0 0.3 0.16" size="0.06"/>
      </body>
      <body name="right wheel2" pos="-0.45 -1.2 0" euler="-90 0 0">
        <geom type = "cylinder" size=".58 .12" rgba=".2 .4 .7 1"/>
        <joint name="right joint2" type="hinge" pos="0 0 0" axis="0 0 1"/>
        <site name="jr2" type="cylinder" pos="0 0 0.16" size="0.1 0.3"/>
        <site name="mr2" type="sphere" pos="0 0.3 -0.16" size="0.06"/>
      </body>
      <body name="front wheel2" pos="0.5 0 -0.39">
        <geom type="sphere" size="0.19" rgba=".5 .7 .8 1"/>
        <joint name="sphere wj2" type="ball" pos="0 0 0"/>
      </body>
    </body>
  </worldbody>

  <actuator>
    <motor name="left motor1" joint="left joint1"/>
    <motor name="right motor1" joint="right joint1"/>
    <motor name="left motor2" joint="left joint2"/>
    <motor name="right motor2" joint="right joint2"/>
    <position name="left wheel pos1" joint="left joint1" kp="50"/>
    <velocity name="left wheel vel1" joint="left joint1" kv="10"/>
    <position name="right wheel pos1" joint="right joint1" kp="50"/>
    <velocity name="right wheel vel1" joint="right joint1" kv="10"/>
    <position name="left wheel pos2" joint="left joint2" kp="50"/>
    <velocity name="left wheel vel2" joint="left joint2" kv="10"/>
    <position name="right wheel pos2" joint="right joint2" kp="50"/>
    <velocity name="right wheel vel2" joint="right joint2" kv="10"/>
  </actuator>

</mujoco>
